Workbook

Sheet Summary
A1: Parcis Zoning Reports
A2: City of Toronto · 2 lots · as-of-right envelope, the lot's history and Committee of Adjustment precedent nearby · runs 30 Sep 2026 · source: City of Toronto Open Data · Parcis · © 2026 Joshua Seaton. All rights reserved. Evaluation copy.
A4: LOT | C4: AS OF RIGHT | F4: THIS LOT | H4: NEIGHBOUR PRECEDENT | P4: SIGNS OF CHANGE | S4: DATA | T4: OPEN
A5: Address | B5: Ward | C5: Zone | D5: Max height (m) | E5: Max FSI | F5: Last decision | G5: Permit | H5: Radius (m) | I5: Applications | J5: Approved | K5: Decided | L5: Approval rate | M5: Precedent | N5: 3-storey new houses approved | O5: Weeks to hearing | P5: Awaiting hearing | Q5: Severance attempts | R5: Rezonings / OPAs (OZ) | S5: Data check | T5: Report | U5: Map | V5: Street View
A6: 32 Ardmore Rd | B6: Toronto–St. Paul's | C6: RD (f12.0; d0.65) (x1321) | D6: 12 | E6: 0.65 | F6: Minor variance approved 29 Sep 2021 | G6: New-building permit issued Feb 2022, under inspection | H6: 250 | I6: =COUNTIFS(Applications!$A:$A,$A6) -> 45 | J6: =COUNTIFS(Applications!$A:$A,$A6,Applications!$I:$I,"Approved") -> 37 | K6: =COUNTIFS(Applications!$A:$A,$A6,Applications!$I:$I,"Approved")+COUNTIFS(Applications!$A:$A,$A6,Applications!$I:$I,"Refused") -> 39 | L6: =IF(K6>0,J6/K6,"") -> 0.94871795 | M6: Strong precedent | N6: =COUNTIFS(Applications!$A:$A,$A6,Applications!$G:$G,"New house",Applications!$I:$I,"Approved",Applications!$H:$H,3) -> 15 | O6: 8 | P6: =COUNTIFS(Applications!$A:$A,$A6,Applications!$I:$I,"Awaiting hearing") -> 1 | Q6: =COUNTIFS(Applications!$A:$A,$A6,Applications!$G:$G,"Severance or consent") -> 2 | R6: =COUNTIFS('Development Applications'!$A:$A,$A6,'Development Applications'!$F:$F,"Official Plan Amendment / Rezoning") -> 0 | S6: ✓ All 11 sources checked | T6: Open report | U6: Map | V6: Street View
A7: 65 Bristol Ave | B7: Davenport | C7: R (d0.6) (x739) | D7: 13 | E7: 0.6 | F7: Minor variance approved 9 Nov 2022 | G7: New-building permit issued Jun 2026, with a revision issued | H7: 250 | I7: =COUNTIFS(Applications!$A:$A,$A7) -> 25 | J7: =COUNTIFS(Applications!$A:$A,$A7,Applications!$I:$I,"Approved") -> 20 | K7: =COUNTIFS(Applications!$A:$A,$A7,Applications!$I:$I,"Approved")+COUNTIFS(Applications!$A:$A,$A7,Applications!$I:$I,"Refused") -> 21 | L7: =IF(K7>0,J7/K7,"") -> 0.95238095 | M7: Strong precedent | N7: =COUNTIFS(Applications!$A:$A,$A7,Applications!$G:$G,"New house",Applications!$I:$I,"Approved",Applications!$H:$H,3) -> 2 | O7: 11 | P7: =COUNTIFS(Applications!$A:$A,$A7,Applications!$I:$I,"Awaiting hearing") -> 0 | Q7: =COUNTIFS(Applications!$A:$A,$A7,Applications!$G:$G,"Severance or consent") -> 1 | R7: =COUNTIFS('Development Applications'!$A:$A,$A7,'Development Applications'!$F:$F,"Official Plan Amendment / Rezoning") -> 1 | S7: ✓ All 11 sources checked | T7: Open report | U7: Map | V7: Street View
A9: Click an address for its one-page brief, Open report for the interactive map and tables, or go to the Applications, Permits and Development Applications sheets for every record. Each record opens the City's own page for it (or its search page, with the number to paste); the last column of each record sheet opens the raw Open Data row.
A10: Precedent: approved ÷ decided (approved or refused) Committee of Adjustment files within the radius. Strong ≥ 80%, Mixed 50–79%, Weak < 50%; fewer than 3 decided files is too few to call.
A11: Counts are formulas over the Applications sheet, so they update if you edit it. Weeks to hearing is a median; hover the cell for its basis.

Sheet 32 Ardmore Rd
A1: 32 Ardmore Rd | I1: RD
A2: Toronto–St. Paul's · Postal area M5P · 250 m radius · Run 30 Sep 2026 · Parcis · © 2026 Joshua Seaton. All rights reserved. Evaluation copy.
A3: ← Summary | B3: Interactive report | D3: Google Maps | E3: Street View | F3: City zoning map | H3: All 45 applications →
A5: BOTTOM LINE
A6: Strong precedent: 37 of 39 decided applications within 250 m were approved (95%).
A7: The lot's recent approval history demonstrates administrative readiness: a minor variance was approved 152 days after filing in 2021, and the resulting new-house permit 22 111410 is now under inspection. Site-specific exception 1321 may modify the base RD zone rules of minimum lot frontage 12.0 m and maximum floor space index 0.65, so the exception's specific provisions warrant careful review. Neighbour precedent strongly supports approval prospects, with 37 of 39 decided applications approved (95%) within 250 m, including 15 three-storey new houses that demonstrate the area's receptiveness to residential intensification. The median time from filing to hearing across 9 decided files in the last three years is 8 weeks, providing a baseline for timeline planning. The developer should confirm the exact scope of site-specific exception 1321 and ensure the current project aligns with the variance already granted under A0554/21TEY.
A8: Written by Claude (zoning-narrative-claude-haiku-4-5) from the computed facts; every number in it was checked against them before use.
A10: KEY NUMBERS
A11: Applications within 250 m | C11: Approval rate | E11: Weeks to hearing | G11: New houses approved | I11: Awaiting hearing
A12: =COUNTIFS(Applications!$A:$A,"32 Ardmore Rd") -> 45 | C12: =IFERROR(COUNTIFS(Applications!$A:$A,"32 Ardmore Rd",Applications!$I:$I,"Approved")/(COUNTIFS(Applications!$A:$A,"32 Ardmore Rd",Applications!$I:$I,"Approved")+COUNTIFS(Applications!$A:$A,"32 Ardmore Rd",Applications!$I:$I,"Refused")),"–") -> 0.94871795 | E12: 8 | G12: =COUNTIFS(Applications!$A:$A,"32 Ardmore Rd",Applications!$G:$G,"New house",Applications!$I:$I,"Approved") -> 22 | I12: =COUNTIFS(Applications!$A:$A,"32 Ardmore Rd",Applications!$I:$I,"Awaiting hearing") -> 1
A13: Committee of Adjustment files | C13: 37 of 39 decided | E13: median, last 3 yrs (9 files) | G13: 15 of them three storeys | I13: filed, not yet heard
A15: WHAT YOU CAN BUILD AS-OF-RIGHT
A16: Zone string decoded, plus the overlays and plans on top of it. The decoder reads the label only; read the by-law and any exception before design.
A17: Zone | D17: RD (f12.0; d0.65) (x1321) Residential Detached zone | I17: By-law chapter
A18: f12.0 | D18: Minimum lot frontage 12.0 m Matters for any severance.
A19: d0.65 | D19: Maximum floor space index 0.65 Gross floor area up to 0.65 × lot area.
A20: x1321 | D20: Site-specific exception 1321 Can change the standard rules; read it before design. | I20: Exception text
A21: Maximum height | D21: 12 m Height overlay HT 12.0
A22: Lot coverage overlay | D22: No lot coverage overlay at this lot Nearest coverage area is about 1.6 km away.
A23: Building setback overlay | D23: None at this lot
A24: Secondary plan | D24: None
A25: Site and area specific policy | D25: None
A26: Zone source | D26: City zoning map Matches variance file A0554/21TEY
A28: THIS LOT'S HISTORY
A29: Minor variance A0554/21TEY approved 29 Sep 2021, 152 days after filing; new-house permit 22 111410 issued 23 Feb 2022, now under inspection.
A30: Date | B30: What happened | E30: File or permit | G30: Detail | J30: Source
A31: 44316 | B31: Minor variance filed | E31: A0554/21TEY | G31: To construct a two-storey detached dwelling with a rear ground floor terrace. | J31: Request from CoA staff
A32: 44468 | B32: Variance approved by the Committee of Adjustment | E32: A0554/21TEY | G32: 152 days after filing. | J32: Request from CoA staff
A33: 44599 | B33: New-building permit applied for | E33: 22 111410 | G33: Proposal to construct a new 2 storey SFD-detached dwelling with an integral garage and a finished basement. | J33: Check permit status
A34: 44599 | B34: Demolition permit applied for | E34: 22 111400 | G34: Proposal to demolish the existing 2 storey SFD-detached dwelling. | J34: Building records request
A35: 44615 | B35: New-building permit issued | E35: 22 111410 | G35: Estimated cost $1,000,000. Cites variance A0554/21TEY. | J35: Check permit status
A36: 44628 | B36: Demolition permit issued | E36: 22 111400 | J36: Building records request
A37: 46063 | B37: Demolition permit closed | E37: 22 111400 | J37: Building records request
A38: 46295 | B38: Status at this run | E38: 22 111410 | G38: Permit 22 111410: under inspection. | J38: Check permit status
A40: WHAT THE NEIGHBOURS GOT APPROVED WITHIN 250 M
A41: Counts are live formulas over the Applications sheet. Approval rate counts approved and refused decisions only.
A42: Project type | D42: Applications | E42: Approved | F42: Refused | G42: Awaiting hearing | H42: Not decided | I42: Approval rate
A43: New house | D43: =COUNTIFS(Applications!$A:$A,"32 Ardmore Rd",Applications!$G:$G,"New house") -> 26 | E43: =COUNTIFS(Applications!$A:$A,"32 Ardmore Rd",Applications!$G:$G,"New house",Applications!$I:$I,"Approved") -> 22 | F43: =COUNTIFS(Applications!$A:$A,"32 Ardmore Rd",Applications!$G:$G,"New house",Applications!$I:$I,"Refused") -> 1 | G43: =COUNTIFS(Applications!$A:$A,"32 Ardmore Rd",Applications!$G:$G,"New house",Applications!$I:$I,"Awaiting hearing") -> 1 | H43: =COUNTIFS(Applications!$A:$A,"32 Ardmore Rd",Applications!$G:$G,"New house",Applications!$I:$I,"Not decided") -> 2 | I43: =IF(E43+F43>0,E43/(E43+F43),"–") -> 0.95652174
A44: Addition or alteration | D44: =COUNTIFS(Applications!$A:$A,"32 Ardmore Rd",Applications!$G:$G,"Addition or alteration") -> 10 | E44: =COUNTIFS(Applications!$A:$A,"32 Ardmore Rd",Applications!$G:$G,"Addition or alteration",Applications!$I:$I,"Approved") -> 9 | F44: =COUNTIFS(Applications!$A:$A,"32 Ardmore Rd",Applications!$G:$G,"Addition or alteration",Applications!$I:$I,"Refused") -> 0 | G44: =COUNTIFS(Applications!$A:$A,"32 Ardmore Rd",Applications!$G:$G,"Addition or alteration",Applications!$I:$I,"Awaiting hearing") -> 0 | H44: =COUNTIFS(Applications!$A:$A,"32 Ardmore Rd",Applications!$G:$G,"Addition or alteration",Applications!$I:$I,"Not decided") -> 1 | I44: =IF(E44+F44>0,E44/(E44+F44),"–") -> 1
A45: Pool, deck or exterior | D45: =COUNTIFS(Applications!$A:$A,"32 Ardmore Rd",Applications!$G:$G,"Pool, deck or exterior") -> 5 | E45: =COUNTIFS(Applications!$A:$A,"32 Ardmore Rd",Applications!$G:$G,"Pool, deck or exterior",Applications!$I:$I,"Approved") -> 5 | F45: =COUNTIFS(Applications!$A:$A,"32 Ardmore Rd",Applications!$G:$G,"Pool, deck or exterior",Applications!$I:$I,"Refused") -> 0 | G45: =COUNTIFS(Applications!$A:$A,"32 Ardmore Rd",Applications!$G:$G,"Pool, deck or exterior",Applications!$I:$I,"Awaiting hearing") -> 0 | H45: =COUNTIFS(Applications!$A:$A,"32 Ardmore Rd",Applications!$G:$G,"Pool, deck or exterior",Applications!$I:$I,"Not decided") -> 0 | I45: =IF(E45+F45>0,E45/(E45+F45),"–") -> 1
...

Sheet 65 Bristol Ave
A1: 65 Bristol Ave | I1: R
A2: Davenport · Postal area M6H · 250 m radius · Run 30 Sep 2026 · Parcis · © 2026 Joshua Seaton. All rights reserved. Evaluation copy.
A3: ← Summary | B3: Interactive report | D3: Google Maps | E3: Street View | F3: City zoning map | H3: All 25 applications →
A5: BOTTOM LINE
A6: Strong precedent: 20 of 21 decided applications within 250 m were approved (95%).
A7: The lot's own history shows initial resistance to a variance request in February 2022, but a revised application was approved 124 days after filing in November 2022, suggesting that design modifications can overcome initial concerns. Neighbour precedent is strongly favourable: within 250 m, 20 of 21 decided applications were approved, including 2 three-storey new houses, which signals receptiveness to residential intensification in this area. The median time from filing to hearing across 8 decided files in the last three years is 11 weeks, providing a benchmark for timeline expectations. The current new-house permit 23 133661 is now with a revision issued, which aligns with the pattern seen in this lot's own approval history where revisions led to success. The developer should note that while the by-right envelope is 13 m height with no lot coverage overlay and there is no secondary plan or site and area specific policy governing this address, the strong approval precedent (95% approval rate among neighbours) suggests that applications meeting or respecting neighbourhood character are likely to advance.
A8: Written by Claude (zoning-narrative-claude-haiku-4-5) from the computed facts; every number in it was checked against them before use.
A10: KEY NUMBERS
A11: Applications within 250 m | C11: Approval rate | E11: Weeks to hearing | G11: New houses approved | I11: Awaiting hearing
A12: =COUNTIFS(Applications!$A:$A,"65 Bristol Ave") -> 25 | C12: =IFERROR(COUNTIFS(Applications!$A:$A,"65 Bristol Ave",Applications!$I:$I,"Approved")/(COUNTIFS(Applications!$A:$A,"65 Bristol Ave",Applications!$I:$I,"Approved")+COUNTIFS(Applications!$A:$A,"65 Bristol Ave",Applications!$I:$I,"Refused")),"–") -> 0.95238095 | E12: 11 | G12: =COUNTIFS(Applications!$A:$A,"65 Bristol Ave",Applications!$G:$G,"New house",Applications!$I:$I,"Approved") -> 6 | I12: =COUNTIFS(Applications!$A:$A,"65 Bristol Ave",Applications!$I:$I,"Awaiting hearing") -> 0
A13: Committee of Adjustment files | C13: 20 of 21 decided | E13: median, last 3 yrs (8 files) | G13: 2 of them three storeys | I13: filed, not yet heard
A15: WHAT YOU CAN BUILD AS-OF-RIGHT
A16: Zone string decoded, plus the overlays and plans on top of it. The decoder reads the label only; read the by-law and any exception before design.
A17: Zone | D17: R (d0.6) (x739) Residential zone | I17: By-law chapter
A18: d0.6 | D18: Maximum floor space index 0.6 Gross floor area up to 0.6 × lot area.
A19: x739 | D19: Site-specific exception 739 Can change the standard rules; read it before design. | I19: Exception text
A20: Maximum height | D20: 13 m Height overlay HT 13.0
A21: Lot coverage overlay | D21: No lot coverage overlay at this lot Nearest coverage area is about 3.6 km away.
A22: Building setback overlay | D22: None at this lot
A23: Secondary plan | D23: None
A24: Site and area specific policy | D24: None
A25: Zone source | D25: City zoning map Variance file lists R(d0.6) (x739)
A27: THIS LOT'S HISTORY
A28: Minor variance A1344/21TEY was refused 23 Feb 2022; a revised application, A0927/22TEY, was approved 9 Nov 2022, 124 days after filing; new-house permit 23 133661 issued 29 Jun 2026, now with a revision issued.
A29: Date | B29: What happened | E29: File or permit | G29: Detail | J29: Source
A30: 44495 | B30: Minor variance filed | E30: A1344/21TEY | G30: To alter the existing one-storey detached dwelling by constructing a two-and-one-half-storey addition above the existing dwelling. Also, the partial fourth storey will be a loft with a rear fourth storey terrace. Furthermore, three secondary suites will be added. | J30: Request from CoA staff
A31: 44615 | B31: Variance refused by the Committee of Adjustment | E31: A1344/21TEY | G31: 120 days after filing. | J31: Request from CoA staff
A32: 44750 | B32: Minor variance filed | E32: A0927/22TEY | G32: To alter the existing one-storey detached dwelling by constructing complete second and third storey additions, a new front porch and basement walkout, and rear second and third storeys balconies. The altered dwelling will have one primary unit and three secondary suites (four-plex). | J32: Request from CoA staff
A33: 44874 | B33: Variance approved by the Committee of Adjustment | E33: A0927/22TEY | G33: 124 days after filing. | J33: Request from CoA staff
A34: 45029 | B34: Demolition permit applied for | E34: 23 133607 | G34: Proposal to demolish the existing 1 storey SFD-detached dwelling. | J34: Building records request
A35: 45345 | B35: Demolition permit issued | E35: 23 133607 | J35: Building records request
A36: 45521 | B36: Building permit applied for | E36: 24 199858 | G36: Proposal for demolish existing shed and build new garden suite | J36: Building records request
A37: 45569 | B37: Building permit issued | E37: 24 199858 | G37: Estimated cost $400,000. | J37: Building records request
A38: 46114 | B38: Demolition permit closed | E38: 23 133607 | J38: Building records request
A39: 46196 | B39: New-building permit applied for | E39: 23 133661 | G39: Revision 02: basement layout changesREV: Proposal for structural revisionProposal to construct a new 3 storey detached dwelling with 4 units.See also 23 133607 DEM, 21 171077 ZZC, 22 174028 MV and Final and Binding A0927/22TEY. | J39: Check permit status
A40: 46202 | B40: New-building permit issued | E40: 23 133661 | G40: Estimated cost $1,000,000. Cites variance A0927/22TEY. | J40: Check permit status
A41: 46225 | B41: Building permit closed | E41: 24 199858 | J41: Building records request
A42: 46295 | B42: Status at this run | E42: 23 133661 | G42: Permit 23 133661: with a revision issued. | J42: Check permit status
A44: WHAT THE NEIGHBOURS GOT APPROVED WITHIN 250 M
A45: Counts are live formulas over the Applications sheet. Approval rate counts approved and refused decisions only.
...

Sheet Applications
A1: Committee of Adjustment applications near each lot
A2: Every minor variance and consent file within each lot's radius. Filter Lot to see one lot. Documents says where to get the file's papers (its AIC page, or CoA staff and the Research Request Portal); Raw City data opens the Open Data row. · Parcis · © 2026 Joshua Seaton. All rights reserved. Evaluation copy.
A3: ← Summary
A4: Lot | B4: Dist. (m) | C4: Address | D4: File | E4: Documents | F4: Application | G4: Project type | H4: Storeys | I4: Outcome | J4: Decision on file | K4: Filed | L4: Hearing | M4: Weeks to hearing | N4: Appeal | O4: Built under permit | P4: What was asked | Q4: Map | R4: Raw City data
A5: 32 Ardmore Rd | B5: 21 | C5: 200 Vesta Dr | D5: A0385/18TEY | E5: Request from CoA staff | F5: Minor variance | G5: New house | H5: 2.5 | I5: Approved | J5: Approved | K5: 43201 | L5: 43369 | M5: 24 | P5: To construct a new 2-½ storey detached dwelling with integral garage and rear ground floor deck. | Q5: Map | R5: Raw data
A6: 32 Ardmore Rd | B6: 52 | C6: 123 Glenayr Rd | D6: A1347/19TEY | E6: Request from CoA staff | F6: Minor variance | G6: New house | H6: 3 | I6: Approved | J6: Approved | K6: 43829 | L6: 44090 | M6: 37 | O6: 21 151544 | P6: To construct a new three-storey detached dwelling with side integral garage, rear ground floor deck, and front porch. | Q6: Map | R6: Raw data
A7: 32 Ardmore Rd | B7: 60 | C7: 201 Vesta Dr | D7: A0276/24TEY | E7: Request from CoA staff | F7: Minor variance | G7: Pool, deck or exterior | I7: Approved | J7: Approved | K7: 45370 | L7: 45420 | M7: 7 | P7: To construct a new one-storey ancillary structure (covered cabana), and an in-ground swimming pool (including pool equipment), in the rear yard. The existing two-and-one-half-storey detached dwelling will be maintained and unaltered. | Q7: Map | R7: Raw data
A8: 32 Ardmore Rd | B8: 79 | C8: 215 Glenayr Rd | D8: A0286/17TEY | E8: Request from CoA staff | F8: Minor variance | G8: Addition or alteration | H8: 3 | I8: Approved | J8: Approved | K8: 42804 | L8: 42942 | M8: 20 | P8: To alter the approved building permit plans for alterations to a two-storey detached dwelling by constructing a third floor addition. | Q8: Map | R8: Raw data
A9: 32 Ardmore Rd | B9: 96 | C9: 210 Glenayr Rd | D9: A1119/21TEY | E9: Request from CoA staff | F9: Minor variance | G9: New house | H9: 3 | I9: Approved | J9: Approved | K9: 44439 | L9: 44573 | M9: 19 | P9: To construct a new three-storey detached dwelling with an integral garage, a front porch, a rear patio, a rear basement walkout, a second storey front balcony, and second and third storey rear balconies. | Q9: Map | R9: Raw data
A10: 32 Ardmore Rd | B10: 108 | C10: 212 Glenayr Rd | D10: A0670/23TEY | E10: Request from CoA staff | F10: Minor variance | G10: New house | H10: 3 | I10: Approved | J10: Approved | K10: 45134 | L10: 45189 | M10: 8 | P10: To construct a new three-storey detached dwelling with a ground level front integral garage (including a car lift), a rear ground level deck and patio, a rear second floor balcony, front and rear third floor balconies, and a rear basement walkout (with stairs). Also, to construct a rear in-ground swimming pool. | Q10: Map | R10: Raw data
A11: 32 Ardmore Rd | B11: 114 | C11: 218 Vesta Dr | D11: A0026/22TEY | E11: Request from CoA staff | F11: Minor variance | G11: Legalize existing work | I11: Refused | J11: Refused | K11: 44544 | L11: 44650 | M11: 15 | P11: To legalize and to maintain the rear ground floor deck and rear basement addition which were constructed without the benefit of a building permit. | Q11: Map | R11: Raw data
A12: 32 Ardmore Rd | B12: 114 | C12: 218 Vesta Dr | D12: A0787/17TEY | E12: Request from CoA staff | F12: Minor variance | G12: New house | H12: 2 | I12: Approved | J12: Approved | K12: 42933 | L12: 43047 | M12: 16 | P12: To construct a new two-storey detached dwelling with an integral garage. | Q12: Map | R12: Raw data
A13: 32 Ardmore Rd | B13: 125 | C13: 216 Glenayr Rd | D13: A1123/18TEY | E13: Request from CoA staff | F13: Minor variance | G13: New house | H13: 2 | I13: Approved | J13: Approved | K13: 43431 | L13: 43544 | M13: 16 | P13: To construct a new two-storey detached dwelling. | Q13: Map | R13: Raw data
A14: 32 Ardmore Rd | B14: 130 | C14: 16 Ardmore Rd | D14: A1011/16TEY | E14: Request from CoA staff | F14: Minor variance | G14: New house | H14: 2 | I14: Approved | J14: Approved | K14: 42660 | L14: 42781 | M14: 17 | P14: To construct a new two-storey detached dwewlling with below-grade integral garage. | Q14: Map | R14: Raw data
A15: 32 Ardmore Rd | B15: 131 | C15: 201 Rosemary Rd | D15: A1279/19TEY | E15: Request from CoA staff | F15: Minor variance | G15: New house | H15: 3 | I15: Approved | J15: Approved | K15: 43808 | L15: 44034 | M15: 32 | P15: To construct a new three-storey detached house with an integral stacked parking garage, rear basement walkout, rear deck and front and rear second storey balconies. | Q15: Map | R15: Raw data
A16: 32 Ardmore Rd | B16: 133 | C16: 107 Vesta Dr | D16: A0251/20TEY | E16: Request from CoA staff | F16: Minor variance | G16: Legalize existing work | I16: Approved | J16: Approved | K16: 43886 | L16: 44069 | M16: 26 | P16: To legalize and maintain the landscaping, decks and shed to the rear of the existing 2 ½-storey detached house, constructed without proper authorization. | Q16: Map | R16: Raw data
A17: 32 Ardmore Rd | B17: 136 | C17: 207 Rosemary Rd | D17: A1233/21TEY | E17: Request from CoA staff | F17: Minor variance | G17: New house | H17: 3 | I17: Approved | J17: Approved | K17: 44460 | L17: 44587 | M17: 18 | P17: To construct a new three-storey detached dwelling with an integral garage and rear basement walkout. | Q17: Map | R17: Raw data
A18: 32 Ardmore Rd | B18: 145 | C18: 16 Silverwood Ave | D18: A0410/24TEY | E18: Request from CoA staff | F18: Minor variance | G18: New house | H18: 3 | I18: Refused | J18: Refused | K18: 45415 | L18: 45476 | M18: 9 | P18: To construct a new three-storey detached dwelling with an integral garage, a rear ground floor deck with stairs, and a rear third floor balcony. | Q18: Map | R18: Raw data
A19: 32 Ardmore Rd | B19: 145 | C19: 16 Silverwood Ave | D19: A0662/24TEY | E19: Request from CoA staff | F19: Minor variance | G19: New house | H19: 3 | I19: Approved | J19: Approved | K19: 45503 | L19: 45560 | M19: 8 | P19: To construct a new three-storey detached dwelling with an integral garage, a rear ground floor deck with stairs, and a front driveway. | Q19: Map | R19: Raw data
A20: 32 Ardmore Rd | B20: 149 | C20: 213 Rosemary Rd | D20: A0012/24TEY | E20: Request from CoA staff | F20: Minor variance | G20: New house | H20: 2.5 | I20: Approved | J20: Approved | K20: 45288 | L20: 45343 | M20: 8 | P20: To construct a new detached two-and-a-half storey dwelling including a front integral garage with canopy above, a first storey front bay window (cantilevered), a rear basement walkout, a cantilevered front second floor with roof deck above, and a rear second storey roof deck. The existing two-and-a-half storey dwelling will be demolished. | Q20: Map | R20: Raw data
A21: 32 Ardmore Rd | B21: 153 | C21: 21 Elderwood Dr | D21: A0382/24TEY | E21: Request from CoA staff | F21: Minor variance | G21: New house | H21: 3 | I21: Approved | J21: Approved | K21: 45404 | L21: 45455 | M21: 7 | P21: To construct a new three-storey detached dwelling with an integral garage, a front covered porch, and rear ground floor covered and uncovered decks. | Q21: Map | R21: Raw data
A22: 32 Ardmore Rd | B22: 162 | C22: 9 Silverwood Ave | D22: A0686/18TEY | E22: Request from CoA staff | F22: Minor variance | G22: Addition or alteration | I22: Approved | J22: Approved | K22: 43293 | L22: 43446 | M22: 22 | P22: To alter the existing 2½-storey detached dwelling by constructing a two-storey rear addition. | Q22: Map | R22: Raw data
A23: 32 Ardmore Rd | B23: 165 | C23: 108 Glenayr Rd | D23: A0270/22TEY | E23: Request from CoA staff | F23: Minor variance | G23: New house | H23: 3 | I23: Approved | J23: Approved | K23: 44622 | L23: 44720 | M23: 14 | P23: To construct a new three-storey detached dwelling with a rear first storey patio, a front first storey porch, and rear second and third storey balconies. | Q23: Map | R23: Raw data
A24: 32 Ardmore Rd | B24: 166 | C24: 105 Glenayr Rd | D24: A1001/16TEY | E24: Request from CoA staff | F24: Minor variance | G24: New house | H24: 3 | I24: Approved | J24: Approved | K24: 42656 | L24: 42766 | M24: 16 | P24: To construct a new three-storey detached dwelling. | Q24: Map | R24: Raw data
A25: 32 Ardmore Rd | B25: 168 | C25: 34 Hawarden Cres | D25: A0782/20TEY | E25: Request from CoA staff | F25: Minor variance | G25: Pool, deck or exterior | I25: Approved | J25: Approved | K25: 44085 | L25: 44167 | M25: 12 | P25: To construct an outdoor swimming pool in the front yard of the detached two-storey dwelling, located on a corner lot. | Q25: Map | R25: Raw data
A26: 32 Ardmore Rd | B26: 178 | C26: 106 Glenayr Rd | D26: A0074/21TEY | E26: Request from CoA staff | F26: Minor variance | G26: New house | H26: 3 | I26: Approved | J26: Approved | K26: 44217 | L26: 44349 | M26: 19 | P26: To construct a new three-storey detached dwelling with an integral garage, rear basement walkout, rear deck and a front porch. | Q26: Map | R26: Raw data
A27: 32 Ardmore Rd | B27: 180 | C27: 200 Rosemary Rd | D27: A1151/20TEY | E27: Request from CoA staff | F27: Minor variance | G27: Pool, deck or exterior | I27: Approved | J27: Approved | K27: 44175 | L27: 44334 | M27: 23 | P27: To construct an outdoor swimming pool in the rear yard of the existing three-storey detached house. | Q27: Map | R27: Raw data
A28: 32 Ardmore Rd | B28: 182 | C28: 32 Hawarden Cres | D28: A1016/17TEY | E28: Request from CoA staff | F28: Minor variance | G28: Addition or alteration | I28: Approved | J28: Approved | K28: 42999 | L28: 43159 | M28: 23 | P28: To alter the three-storey detached dwelling by constructing a one-storey east side addition and dormers on the second floor. | Q28: Map | R28: Raw data
A29: 32 Ardmore Rd | B29: 184 | C29: 206 Rosemary Rd | D29: A0598/22TEY | E29: Request from CoA staff | F29: Minor variance | G29: New house | H29: 3 | I29: Approved | J29: Approved | K29: 44687 | L29: 44804 | M29: 17 | P29: To construct a three-storey detached dwelling with a front integral garage, rear balconies on the second and third storeys, and a rear covered terrace on the ground level. The existing shed and pool will be maintained. | Q29: Map | R29: Raw data
A30: 32 Ardmore Rd | B30: 187 | C30: 20 Elderwood Dr | D30: A0998/17TEY | E30: Request from CoA staff | F30: Minor variance | G30: New house | H30: 2 | I30: Approved | J30: Approved | K30: 42992 | L30: 43159 | M30: 24 | P30: To construct a new two-storey detached dwelling with an integral garage and rear ground floor terrace. | Q30: Map | R30: Raw data
A31: 32 Ardmore Rd | B31: 191 | C31: 210 Rosemary Rd | D31: A0568/26TEY | E31: Open on City site | F31: Minor variance | G31: New house | H31: 3 | I31: Awaiting hearing | J31: Awaiting hearing | K31: 46232 | P31: To construct a new three-storey detached dwelling (including a third storey loft) with a front integral three-car garage, a covered front second floor porch with stairs and a landing, a front third storey platform (not accessible), a rear ground floor walkout, a rear second floor deck with stairs, a side (south) ground floor entrance, a rear third storey dormer with a balcony, a side (south) third storey dormer and a side (north) third storey dormer. | Q31: Map | R31: Raw data
A32: 32 Ardmore Rd | B32: 194 | C32: 300 Glenayr Rd | D32: A0473/26TEY | E32: Open on City site | F32: Minor variance | G32: Pool, deck or exterior | I32: Approved | J32: Approved | K32: 46195 | L32: 46274 | M32: 11 | P32: To install a concrete pad and walkway (amenity space) in the front (south) yard, abutting Elderwood Drive. The existing two-storey detached dwelling will be maintained and unaltered. | Q32: Map | R32: Raw data
A33: 32 Ardmore Rd | B33: 196 | C33: 212 Rosemary Rd | D33: A0044/26TEY | E33: Request from CoA staff | F33: Minor variance | G33: New house | H33: 3 | I33: Approved | J33: Approved | K33: 46038 | L33: 46099 | M33: 9 | P33: To construct a new three-storey detached dwelling with an integral garage and a widened driveway, a covered front porch with stairs, a rear third storey balcony, and a rear partially covered ground floor patio. Also, to construct a new inground swimming pool in the rear yard. The existing rear inground swimming pool and concrete pad will be removed. | Q33: Map | R33: Raw data
A34: 32 Ardmore Rd | B34: 204 | C34: 6 Ardmore Rd | D34: A1221/18TEY | E34: Request from CoA staff | F34: Minor variance | G34: New house | H34: 2 | I34: Approved | J34: Approved | K34: 43461 | L34: 43544 | M34: 12 | P34: To construct a new two-storey detached dwelling with a two-car basement garage. | Q34: Map | R34: Raw data
A35: 32 Ardmore Rd | B35: 214 | C35: 180 Rosemary Rd | D35: A0508/19TEY | E35: Request from CoA staff | F35: Minor variance | G35: Addition or alteration | I35: Approved | J35: Approved | K35: 43593 | L35: 43691 | M35: 14 | P35: To alter the existing two-storey detached dwelling by constructing a rear two-storey addition with a two-storey canopy over the rear ground floor deck. | Q35: Map | R35: Raw data
A36: 32 Ardmore Rd | B36: 221 | C36: 18 Burton Rd | D36: A0591/16TEY | E36: Request from CoA staff | F36: Minor variance | G36: New house | H36: 3 | I36: Approved | J36: Approved | K36: 42517 | L36: 42746 | M36: 33 | P36: To construct a new three-storey detached dwelling with an integral garage. | Q36: Map | R36: Raw data
A37: 32 Ardmore Rd | B37: 221 | C37: 18 Burton Rd | D37: A0793/18TEY | E37: Request from CoA staff | F37: Minor variance | G37: New house | H37: 3 | I37: Approved | J37: Approved | K37: 43328 | L37: 43488 | M37: 23 | P37: To alter construction of a new three-storey detached dwelling, under building permit 17-162496, by constructing a front basement extension. | Q37: Map | R37: Raw data
A38: 32 Ardmore Rd | B38: 223 | C38: 1 Silverwood Ave | D38: A0198/24TEY | E38: Request from CoA staff | F38: Minor variance | G38: Pool, deck or exterior | I38: Approved | J38: Approved | K38: 45344 | L38: 45406 | M38: 9 | P38: To permit a rear second storey balcony, which is currently under construction. | Q38: Map | R38: Raw data
A39: 32 Ardmore Rd | B39: 227 | C39: 21 Robinwood Ave | D39: A0030/20TEY | E39: Request from CoA staff | F39: Minor variance | G39: Addition or alteration | I39: Approved | J39: Approved | K39: 43843 | L39: 44027 | M39: 26 | P39: To alter a 2 ½ storey detached dwelling by constructing a rear one-storey addition with a roof terrace above. | Q39: Map | R39: Raw data
A40: 32 Ardmore Rd | B40: 238 | C40: 2 Silverwood Ave | D40: A0308/26TEY | E40: Open on City site | F40: Minor variance | G40: New house | H40: 3 | I40: Approved | J40: Approved | K40: 46134 | L40: 46183 | M40: 7 | P40: To construct a new three-storey detached dwelling (more than 50% of the existing exterior walls of the dwelling will be removed) with an integral garage (accessed from Silverwood Avenue), a front (south) covered porch with stairs, a rear (north) ground floor deck platform with canopy above, a rear third floor balcony and a modified L-shaped driveway (reduced width from the existing oversized driveway accessed from Spadina Road and Silverwood Avenue). | Q40: Map | R40: Raw data
...

Sheet Permits
A1: Building-permit projects near each lot
A2: Permits grouped into projects by permit-number root. Documents opens the permit status search while the City still lists the permit, else a building records request; Raw City data opens the Open Data rows. · Parcis · © 2026 Joshua Seaton. All rights reserved. Evaluation copy.
A3: ← Summary
A4: Lot | B4: Dist. (m) | C4: Address | D4: Permit | E4: Documents | F4: Category | G4: Permit types | H4: Structure | I4: Status | J4: Applied | K4: Issued | L4: Completed | M4: Est. cost | N4: Cost note | O4: Units | P4: Cites variance | Q4: Description | R4: Map | S4: Raw City data
A5: 32 Ardmore Rd | B5: 21 | C5: 200 Vesta Dr | D5: 18 269470 | E5: Building records request | F5: New building | G5: Mechanical(MS); Plumbing(PS); New Houses; Drain and Site Service | H5: SFD - Detached | I5: closed | J5: 43578 | K5: 43579 | L5: 44165 | M5: 1550000 | O5: 1 | Q5: Revision 01 - revise foundation - footings to grade beams with helical pier due to poor soil conditions [Proposal to demolish existing dwelling and construct new 2 storey Single Family Dwelling with integral garage and a car lift in basement] | R5: Map | S5: Raw data
A6: 32 Ardmore Rd | B6: 21 | C6: 200 Vesta Dr | D6: 18 269479 | E6: Building records request | F6: Demolition | G6: Demolition Folder (DM) | H6: SFD - Detached | I6: closed | J6: 43451 | K6: 43543 | L6: 43984 | N6: Unreliable (zero or out of band) | Q6: Proposal to demolish existing dwelling and construct new 2 storey Single Family Dwelling with integral garage and a car lift in basement | R6: Map | S6: Raw data
A7: 32 Ardmore Rd | B7: 23 | C7: 202 Vesta Dr | D7: 16 249214 | E7: Building records request | F7: Addition or alteration | G7: Small Residential Projects | H7: SFD - Detached | I7: closed | J7: 42683 | K7: 42703 | L7: 43054 | M7: 5000 | Q7: Proposal to construct a wood deck. | R7: Map | S7: Raw data
A8: 32 Ardmore Rd | B8: 41 | C8: 205 Glenayr Rd | D8: 14 135787 | E8: Building records request | F8: Demolition | G8: Demolition Folder (DM) | H8: SFD - Detached | I8: closed | J8: 41729 | K8: 41765 | L8: 42752 | N8: Unreliable (zero or out of band) | Q8: Propoal to demolish existing 2 storey SFD-detached dwelling. | R8: Map | S8: Raw data
A9: 32 Ardmore Rd | B9: 41 | C9: 205 Glenayr Rd | D9: 14 135792 | E9: Building records request | F9: New building | G9: New Houses; Drain and Site Service; Plumbing(PS) | H9: SFD - Detached | I9: under inspection | J9: 41729 | K9: 41765 | M9: 1000000 | O9: 1 | Q9: Rev#1 - Revision to interior layout, equipment space in the attic, removal and relocation of a skylight and revision to rear retaining wall. Proposed New Pool is not part of this BLD permit. A separate POOL PERMIT is required. ORIG. BLD Scope of work: Construct New two storey Single Family Detached dwelling with internal parking, and rear basement walkout and rear deck. See also 14 135787 DEM, 12 123128 ZZC and 12 128775 MV. | R9: Map | S9: Raw data
A10: 32 Ardmore Rd | B10: 44 | C10: 206 Vesta Dr | D10: 02 162159 | E10: Building records request | F10: New building | G10: Residential Building Permit | H10: SFD - Detached | I10: closed | J10: 37477 | K10: 37519 | L10: 44117 | M10: 400000 | Q10: Construct 2 storey detached house with integral at grade garage at front. See C of A Decision dated June 7, 2002. Final and Binding | R10: Map | S10: Raw data
A11: 32 Ardmore Rd | B11: 52 | C11: 123 Glenayr Rd | D11: 21 151527 | E11: Building records request | F11: Demolition | G11: Demolition Folder (DM) | H11: SFD - Detached | I11: cancelled | J11: 44323 | L11: 45299 | N11: Unreliable (zero or out of band) | Q11: Proposal to demolish the existing 2 storey SFD-detached dwelling. | R11: Map | S11: Raw data
A12: 32 Ardmore Rd | B12: 52 | C12: 123 Glenayr Rd | D12: 21 151544 | E12: Building records request | F12: New building | G12: Plumbing(PS); New Houses; Drain and Site Service | H12: SFD - Detached | I12: cancelled | J12: 44323 | L12: 45299 | M12: 1500000 | O12: 1 | P12: A1347/19TEY | Q12: Plumbing - Proposal to construct a new 3 storey SFD-detached dwelling with an integral garage and 2 levels of finished basement. See also 21 151527 DEM, 19 236766 ZZC, 19265483 MV and Final and Binding A1347/19TEY. | R12: Map | S12: Raw data
A13: 32 Ardmore Rd | B13: 52 | C13: 123 Glenayr Rd | D13: 24 219285 | E13: Check permit status | F13: New building | G13: Mechanical(MS); Plumbing(PS); New Houses; Drain and Site Service | H13: SFD - Detached | I13: closed | J13: 45867 | K13: 45910 | L13: 46268 | M13: 1500000 | O13: 1 | Q13: Revision 01 - Basement revision and minor interior change. ---------------------------------------------------------------Three storey dwelling with attached garage, front porch and rear deck | R13: Map | S13: Raw data
A14: 32 Ardmore Rd | B14: 52 | C14: 123 Glenayr Rd | D14: 24 219288 | E14: Building records request | F14: Demolition | G14: Demolition Folder (DM) | H14: SFD - Detached | I14: closed | J14: 45563 | K14: 45603 | L14: 45930 | N14: Unreliable (zero or out of band) | Q14: Demolish the existing two storey dwelling. | R14: Map | S14: Raw data
A15: 32 Ardmore Rd | B15: 53 | C15: 207 Glenayr Rd | D15: 01 185216 | E15: Building records request | F15: Addition or alteration | G15: Residential Building Permit | H15: SFD - Detached | I15: closed | J15: 37176 | K15: 37180 | L15: 44124 | M15: 220000 | Q15: Construct two storey addition at the rear. Make interior alterations and construct uncovered platform at rear. Also demolish private detached garage and maintain parking space. | R15: Map | S15: Raw data
A16: 32 Ardmore Rd | B16: 53 | C16: 207 Glenayr Rd | D16: 04 122828 | E16: Building records request | F16: Addition or alteration | G16: Small Residential Projects | H16: SFD - Detached | I16: closed | J16: 38083 | K16: 38083 | L16: 45833 | M16: 15000 | Q16: Build deck at rear first floor level. | R16: Map | S16: Raw data
A17: 32 Ardmore Rd | B17: 60 | C17: 201 Vesta Dr | D17: 19 150001 | E17: Building records request | F17: Addition or alteration | G17: Plumbing(PS); Small Residential Projects | H17: SFD - Detached | I17: closed | J17: 43591 | K17: 43626 | L17: 43726 | M17: 5000 | Q17: Plumbing - Remove the existing window and install a new fire rated window on the rear side.Remove a partition wall and build a new partition wall in the first floor.Remodel the kitchen cabinets and some minor plumbing works for the kitchen sink. | R17: Map | S17: Raw data
A18: 32 Ardmore Rd | B18: 60 | C18: 201 Vesta Dr | D18: 25 117344 | E18: Building records request | F18: Addition or alteration | G18: Small Residential Projects | H18: SFD - Detached | I18: closed | J18: 45702 | K18: 45714 | L18: 45874 | M18: 150000 | Q18: Proposal for new rear yard covered canopy, new side yard landscaping, retaining walls and stairs to replace existing dure to age. | R18: Map | S18: Raw data
A19: 32 Ardmore Rd | B19: 62 | C19: 121 Glenayr Rd | D19: 04 161888 | E19: Building records request | F19: Addition or alteration | G19: Small Residential Projects | H19: SFD - Detached | I19: closed | J19: 38197 | K19: 38251 | L19: 45867 | M19: 50000 | Q19: Build 1 and 2 storey additions and deck at rear; build platform with roof over a front; and extend bay windows at front. Also build basement entrance at rear. See Committee of Adjustments decision. Approved with conditions. Final and binding. | R19: Map | S19: Raw data
A20: 32 Ardmore Rd | B20: 62 | C20: 121 Glenayr Rd | D20: 19 202328 | E20: Building records request | F20: Other | G20: Drain and Site Service | H20: SFD - Detached | I20: closed | J20: 43685 | K20: 43685 | L20: 43689 | N20: Not declared | Q20: Proposed installation of a new back water valve in an existing single family detached dwelling. | R20: Map | S20: Raw data
A21: 32 Ardmore Rd | B21: 70 | C21: 205 Vesta Dr | D21: 03 123097 | E21: Building records request | F21: Addition or alteration | G21: Small Residential Projects | H21: SFD - Detached | I21: closed | J21: 37721 | K21: 37768 | L21: 44348 | M21: 200000 | Q21: make interior alterations to garage for habitable space see c of a | R21: Map | S21: Raw data
A22: 32 Ardmore Rd | B22: 70 | C22: 211 Glenayr Rd | D22: 08 115422 | E22: Building records request | F22: Demolition | G22: Demolition Folder (DM) | H22: SFD - Detached | I22: closed | J22: 39507 | K22: 39525 | L22: 43290 | N22: Unreliable (zero or out of band) | Q22: Proposal to demolish existing 2 sty SFD. See BLD 08 115432 | R22: Map | S22: Raw data
A23: 32 Ardmore Rd | B23: 70 | C23: 211 Glenayr Rd | D23: 08 115432 | E23: Building records request | F23: New building | G23: Mechanical(MS); Plumbing(PS); New Houses; Drain and Site Service | H23: SFD - Detached | I23: closed | J23: 39570 | K23: 39584 | L23: 46003 | M23: 336000 | O23: 1 | P23: A0007/08TEY | Q23: Plumbing - Proposal to construct a new 2 sty SFD. See Demo 08 115422 and Final & Binding - A0007/08TEY | R23: Map | S23: Raw data
A24: 32 Ardmore Rd | B24: 70 | C24: 205 Vesta Dr | D24: 09 183725 | E24: Building records request | F24: Addition or alteration | G24: Small Residential Projects; Plumbing(PS) | H24: SFD - Detached | I24: under inspection | J24: 40115 | K24: 40121 | L24: 46181 | M24: 20000 | Q24: Plumbing - Interior alterations on ground floor (north side) of existing single family dwelling. | R24: Map | S24: Raw data
A25: 32 Ardmore Rd | B25: 70 | C25: 211 Glenayr Rd | D25: 10 192388 | E25: Building records request | F25: Addition or alteration | G25: Small Residential Projects | H25: SFD - Detached | I25: closed | J25: 40574 | K25: 40582 | L25: 44384 | M25: 10000 | Q25: Revision to existing building permit - revision to change front entrance from flat roof to peak roof.Proposed new front exterior entrance and new gazebo at rear. | R25: Map | S25: Raw data
A26: 32 Ardmore Rd | B26: 76 | C26: 212 Vesta Dr | D26: 10 117622 | E26: Building records request | F26: New building | G26: Plumbing(PS); New Houses; Drain and Site Service | H26: SFD - Detached | I26: closed | J26: 40220 | K26: 40239 | L26: 43486 | M26: 600000 | Q26: SEE NOTE BELOW Scope of Revision changed March7/11 originally to install sprinkler system -Proposal to construct new three-storey single family detached dwelling w/ integral two-car garage and rear deck. See permit 09-194905 and PAL 09-152062 | R26: Map | S26: Raw data
A27: 32 Ardmore Rd | B27: 79 | C27: 215 Glenayr Rd | D27: 16 247050 | E27: Building records request | F27: Addition or alteration | G27: Small Residential Projects | H27: SFD - Detached | I27: closed | J27: 42678 | K27: 42689 | L27: 44109 | M27: 80000 | Q27: Proposal to underpin the basement of the existing single family dwelling. | R27: Map | S27: Raw data
A28: 32 Ardmore Rd | B28: 79 | C28: 215 Glenayr Rd | D28: 17 105960 | E28: Check permit status | F28: Addition or alteration | G28: Plumbing(PS); Mechanical(MS); Small Residential Projects | H28: SFD - Detached | I28: under inspection | J28: 42753 | K28: 42759 | M28: 35000 | Q28: Revision #01 - Changes made to 3rd storey alterations, see attached drawings. Proposed 2 storey rear addition, reconstruct the front wall with front bay window, covered front porch with cold storage beneath, rear ground floor deck and interior alterations throughout the existing detached single family dwelling. **** See ZZC Drawings. **** | R28: Map | S28: Raw data
A29: 32 Ardmore Rd | B29: 79 | C29: 202 Glenayr Rd | D29: 20 190793 | E29: Building records request | F29: Addition or alteration | G29: Small Residential Projects | H29: SFD - Detached | I29: closed | J29: 44159 | K29: 44172 | L29: 44347 | M29: 8000 | Q29: Revision # 01 - For slab on grade with r/c thickened edge; cantilevered slab over tree protection zone.Rear deck | R29: Map | S29: Raw data
A30: 32 Ardmore Rd | B30: 79 | C30: 202 Glenayr Rd | D30: 22 104925 | E30: Building records request | F30: Addition or alteration | G30: Mechanical(MS); Plumbing(PS); Small Residential Projects | H30: SFD - Detached | I30: closed | J30: 44851 | K30: 44853 | L30: 45833 | M30: 100000 | Q30: Plumbing - Proposal for 2nd floor Addition and Interior Alterations to the existing Single Family Dwelling. | R30: Map | S30: Raw data
A31: 32 Ardmore Rd | B31: 79 | C31: 202 Glenayr Rd | D31: 22 141312 | E31: Building records request | F31: Addition or alteration | G31: Plumbing(PS); Small Residential Projects | H31: SFD - Detached | I31: closed | J31: 44683 | K31: 44718 | L31: 45833 | M31: 100000 | Q31: Plumbing - Underpin existing basement and crawlspac, and a basement walkout | R31: Map | S31: Raw data
A32: 32 Ardmore Rd | B32: 80 | C32: 204 Glenayr Rd | D32: 22 206189 | E32: Check permit status | F32: Addition or alteration | G32: Small Residential Projects; Plumbing(PS); Drain and Site Service | H32: SFD - Detached | I32: under inspection | J32: 44824 | K32: 44834 | L32: 45090 | M32: 150000 | Q32: Plumbing - Proposal to alter existing detached SFD with constructing basement underpinning and interior alterations. | R32: Map | S32: Raw data
A33: 32 Ardmore Rd | B33: 88 | C33: 214 Vesta Dr | D33: 10 203724 | E33: Building records request | F33: New building | G33: New Houses; Mechanical(MS); Plumbing(PS) | H33: SFD - Detached | I33: with a revision issued | J33: 40659 | K33: 40668 | L33: 42740 | M33: 600000 | P33: A0327/10TEY | Q33: REVISION: This is a revision to the third floor design including four(4) skylights and a change to the deck at the rear of the ground floor.REVISION - to reduce the size and alter the layout of the 3rd floor.Proposal to construct a new 2 1/2 storey SFD-detached dwelling. See also 10 121737 ZAL, 10 131427 MV, Final and Binding A0327/10TEY and 10 203718 DEM. | R33: Map | S33: Raw data
A34: 32 Ardmore Rd | B34: 88 | C34: 21 Ardmore Rd | D34: 12 196249 | E34: Building records request | F34: Addition or alteration | G34: Plumbing(PS); Small Residential Projects | H34: SFD - Detached | I34: closed | J34: 41079 | K34: 41081 | L34: 44006 | M34: 25000 | Q34: Plumbing - Proposal to construct a 1 storey addition at the rear of an existing 2 storey SFD-detached dwelling. | R34: Map | S34: Raw data
A35: 32 Ardmore Rd | B35: 89 | C35: 117 Glenayr Rd | D35: 19 253113 | E35: Building records request | F35: Addition or alteration | G35: Small Residential Projects | H35: SFD - Detached | I35: closed | J35: 43794 | K35: 43802 | L35: 43802 | M35: 121000 | Q35: Proposal to erect a pool enclosure fence, complete with inground concrete swimming pool. | R35: Map | S35: Raw data
A36: 32 Ardmore Rd | B36: 90 | C36: 112 Vesta Dr | D36: 13 183848 | E36: Building records request | F36: Addition or alteration | G36: Mechanical(MS); Plumbing(PS); Small Residential Projects | H36: SFD - Detached | I36: closed | J36: 41604 | K36: 41612 | L36: 45958 | M36: 500000 | Q36: Plumbing - Proposal for multiple projects to an existing 2 1/2 storey SFD-detached dwelling. Scope of work includes a rear 2 storey addition, a rear second storey addition, interior alterations and basement finishing. See also 13 114303 ZZC and 13 126608 MV. | R36: Map | S36: Raw data
A37: 32 Ardmore Rd | B37: 96 | C37: 210 Glenayr Rd | D37: 22 115526 | E37: Building records request | F37: Demolition | G37: Demolition Folder (DM) | H37: SFD - Detached | I37: closed | J37: 44610 | K37: 44806 | L37: 45461 | N37: Unreliable (zero or out of band) | Q37: Proposal to demolish existing two storey detached dwelling. | R37: Map | S37: Raw data
A38: 32 Ardmore Rd | B38: 96 | C38: 210 Glenayr Rd | D38: 22 115562 | E38: Building records request | F38: New building | G38: Mechanical(MS); Plumbing(PS); New Houses; Drain and Site Service | H38: SFD - Detached | I38: closed | J38: 44610 | K38: 44771 | L38: 45461 | M38: 5000000 | O38: 1 | Q38: REVISION 02: Revision for windows. (Main House). ORIG. BLD - NH - Main House permit: Construct a New 3-Storey SFD Detached House, with an integral garage with a "car elevator", including a basement nanny suite, front porch, a rear balcony, front 3rd storey balcony, rear yard pool, Basement Walkout, rear deck. (Only 1 balcony at rear at 2nd floor). | R38: Map | S38: Raw data
A39: 32 Ardmore Rd | B39: 96 | C39: 210 Glenayr Rd | D39: 22 212360 | E39: Building records request | F39: Addition or alteration | G39: Mechanical(MS); Plumbing(PS); Small Residential Projects | H39: 2 Unit - Detached; Laneway / Rear Yard Suite | I39: closed | J39: 44837 | K39: 44935 | L39: 45461 | M39: 800000 | O39: 1 | Q39: Rev 02: Revisions for windows and location of the furnace room. (GARDEN SUITE) ORIG. Permit: Construct a New 1-Storey Garden Suite (53sqm), at the rear yard of a Single Family Dwelling Detached House. | R39: Map | S39: Raw data
A40: 32 Ardmore Rd | B40: 108 | C40: 212 Glenayr Rd | D40: 24 123645 | E40: Check permit status | F40: New building | G40: New Houses; Plumbing(PS); Drain and Site Service | H40: SFD - Detached | I40: examiner's notice sent | J40: 45359 | M40: 1500000 | O40: 1 | Q40: Plumbing - Proposal to construct a new three-storey detached dwelling with a ground level front integral garage (including a car lift), a rear ground level deck and patio, a rear second floor balcony, front and rear third floor balconies, and a rear basement walkout and rear in-ground swimming pool. See also 23-180571 STE 12 MV | R40: Map | S40: Raw data
...

Sheet Development Applications
A1: Development applications near each lot
A2: Rezonings and Official Plan amendments (OZ), site plans (SA), subdivisions (SB), condominiums (CD) and part lot control (PL). Documents opens the application in the Application Information Centre, or emails Development Review for closed ones; Raw City data opens the Open Data row. · Parcis · © 2026 Joshua Seaton. All rights reserved. Evaluation copy.
A3: ← Summary
A4: Lot | B4: Dist. (m) | C4: Address | D4: Application | E4: Documents | F4: Type | G4: Status | H4: Submitted | I4: Description | J4: Map | K4: Raw City data
A5: 65 Bristol Ave | B5: 119 | C5: 1423 Dufferin St | D5: 26 210726 STE 09 SA | E5: Open on City site | F5: Site Plan Approval | G5: Application Received | H5: 46232 | I5: Proposed 9-storey (28.5 metre) apartment, containing 60 residential units with a total of 3,817 square metres of residential GFA and 122 square metres of commercial GFA. | J5: Map | K5: Raw data
A6: 65 Bristol Ave | B6: 119 | C6: 1423 Dufferin St | D6: 25 240145 STE 09 OZ | E6: Open on City site | F6: Official Plan Amendment / Rezoning | G6: Closed | H6: 45945 | I6: The proposed development replaces the existing vacant 2-storey dwelling with a new 9-storey mixed-use building, containing 60 residential units with a total of 3,961 square metres of residential GFA and 123 square metres of non-residential GFA. | J6: Map | K6: Raw data
A7: 65 Bristol Ave | B7: 149 | C7: 1455 Dufferin St | D7: 14 213788 WET 17 SA | E7: developmentreview@toronto.ca | F7: Site Plan Approval | G7: Closed | H7: 41879 | I7: Proposal to permit the construction of six three-storey townhouse units with integral garages. Parking for the units would be provided via a rear laneway. The existing building would be demolished. | J7: Map | K7: Raw data

Sheet Sources
A1: Sources and method
A2: Where every number comes from, how it's counted, and what this workbook can't tell you. · Parcis · © 2026 Joshua Seaton. All rights reserved. Evaluation copy.
A3: ← Summary
A5: CITY OF TORONTO OPEN DATA USED
A6: Dataset | B6: What it's used for | C6: Link
A7: Committee of Adjustment Applications | B7: Minor variance and consent files for the lot and its neighbours (active, and closed since 2017) | C7: open.toronto.ca
A8: Building Permits - Active Permits | B8: Permits applied for or in progress | C8: open.toronto.ca
A9: Building Permits - Cleared Permits | B9: Permits closed since 2017 | C9: open.toronto.ca
A10: Development Applications | B10: Rezonings and Official Plan amendments near the lot | C10: open.toronto.ca
A11: Zoning By-law 569-2013 | B11: Zone, height, lot coverage and building setback layers at the lot | C11: open.toronto.ca
A12: Secondary Plans | B12: Secondary plan at the lot | C12: open.toronto.ca
A13: Site and Area Specific Policies | B13: Site and area specific policy at the lot | C13: open.toronto.ca
A14: Address Points (Municipal) | B14: Places every record and measures distances | C14: open.toronto.ca
A15: Application Information Centre | B15: Drawings, decisions and documents for open and recently final Committee of Adjustment files and development applications. | C15: toronto.ca
A16: Committee of Adjustment staff | B16: Decision notices for files the AIC no longer lists, and anything older than 10 years. | C16: toronto.ca
A17: Research Request Portal | B17: 10 years of CoA decision notices within 500 m ($150 + HST) or 1,000 m ($300 + HST) of an address. | C17: toronto.ca
... A21: Interactive zoning map | B21: The City's own zoning map, centred on the lot. | C21: toronto.ca
A23: DATA CHECK FOR EACH RUN
A24: "Couldn't be checked" means the City's service wasn't reachable. It is missing data, never a finding that there are no records.
A25: Source | D25: 32 Ardmore Rd 2026-09-30 10:26:20 | E25: 65 Bristol Ave 2026-09-30 10:26:25
A26: This lot's Committee of Adjustment files | D26: Records found | E26: Records found
A27: This lot's building permits | D27: Records found | E27: Records found
A28: Neighbour Committee of Adjustment applications | D28: Records found | E28: Records found
A29: Neighbour building permits | D29: Records found | E29: Records found
A30: Rezoning and Official Plan amendment applications | D30: Checked, none | E30: Records found
A31: Zoning map | D31: Records found | E31: Records found
A32: Height overlay | D32: Records found | E32: Records found
A33: Lot coverage overlay | D33: Checked, none | E33: Checked, none
A34: Building setback overlay | D34: Checked, none | E34: Checked, none
A35: Secondary plans | D35: Checked, none | E35: Checked, none
A36: Site and area specific policies | D36: Checked, none | E36: Checked, none
A38: HOW THE NUMBERS ARE MADE
A39: Decided | B39: Approved or refused. Deferred, withdrawn, awaiting-hearing and closed-without-a-decision files are listed but not counted.
A40: Approval rate | B40: Approved ÷ decided, for Committee of Adjustment files within the radius.
A41: Precedent | B41: Strong: 80% or more approved. Mixed: 50–79%. Weak: under 50%. Too few decisions: fewer than 3 decided files.
A42: Weeks to hearing | B42: Median time from filing to hearing for decided files; "last 3 yrs" counts files filed in the three years before the run. Shown once 3 or more files qualify.
A43: Project type | B43: From the City's application sub-type (new house or addition), refined by keywords for pools and decks, legalizations and severances.
A44: Storeys | B44: Read from the first storey phrase in a new-house description.
A45: Built under permit | B45: A variance counts as built when a building permit's description cites its decision number. That makes it a floor, not a full count.
A46: Permit project | B46: Permits grouped by permit-number root (for example 22 111410 BLD, PLB, DRN and HVA are one project).
...
